<?xml version="1.0" ?>
<robot name="gigaman">
  <link name="torso">
    <inertial>
      <mass value="10"/>
      <inertia ixx="0.01" iyy="0.01" izz="0.01"/>
    </inertial>
    <visual>
      <geometry>
        <box size="0.3 0.2 0.5"/>
      </geometry>
      <material name="torso_color">
        <color rgba="0 0 1 1"/>
      </material>
    </visual>
    <collision>
      <geometry>
        <box size="0.3 0.2 0.5"/>
      </geometry>
    </collision>
  </link>
  <link name="head">
    <inertial>
      <mass value="2"/>
      <inertia ixx="0.01" iyy="0.01" izz="0.01"/>
    </inertial>
    <visual>
      <geometry>
        <box size="0.2 0.2 0.2"/>
      </geometry>
      <material name="head_color">
        <color rgba="1 0.8 0.6 1"/>
      </material>
    </visual>
    <collision>
      <geometry>
        <box size="0.2 0.2 0.2"/>
      </geometry>
    </collision>
  </link>
  <link name="upper_arm_L">
    <inertial>
      <mass value="1"/>
      <inertia ixx="0.01" iyy="0.01" izz="0.01"/>
    </inertial>
    <visual>
      <geometry>
        <box size="0.1 0.1 0.3"/>
      </geometry>
      <material name="upper_arm_L_color">
        <color rgba="1 0 0 1"/>
      </material>
    </visual>
    <collision>
      <geometry>
        <box size="0.1 0.1 0.3"/>
      </geometry>
    </collision>
  </link>
  <link name="lower_arm_L">
    <inertial>
      <mass value="1"/>
      <inertia ixx="0.01" iyy="0.01" izz="0.01"/>
    </inertial>
    <visual>
      <geometry>
        <box size="0.1 0.1 0.3"/>
      </geometry>
      <material name="lower_arm_L_color">
        <color rgba="1 0.5 0 1"/>
      </material>
    </visual>
    <collision>
      <geometry>
        <box size="0.1 0.1 0.3"/>
      </geometry>
    </collision>
  </link>
  <link name="upper_arm_R">
    <inertial>
      <mass value="1"/>
      <inertia ixx="0.01" iyy="0.01" izz="0.01"/>
    </inertial>
    <visual>
      <geometry>
        <box size="0.1 0.1 0.3"/>
      </geometry>
      <material name="upper_arm_R_color">
        <color rgba="1 0 0 1"/>
      </material>
    </visual>
    <collision>
      <geometry>
        <box size="0.1 0.1 0.3"/>
      </geometry>
    </collision>
  </link>
  <link name="lower_arm_R">
    <inertial>
      <mass value="1"/>
      <inertia ixx="0.01" iyy="0.01" izz="0.01"/>
    </inertial>
    <visual>
      <geometry>
        <box size="0.1 0.1 0.3"/>
      </geometry>
      <material name="lower_arm_R_color">
        <color rgba="1 0.5 0 1"/>
      </material>
    </visual>
    <collision>
      <geometry>
        <box size="0.1 0.1 0.3"/>
      </geometry>
    </collision>
  </link>
  <link name="palm_L">
    <inertial>
      <mass value="0.5"/>
      <inertia ixx="0.01" iyy="0.01" izz="0.01"/>
    </inertial>
    <visual>
      <geometry>
        <box size="0.1 0.1 0.1"/>
      </geometry>
      <material name="palm_L_color">
        <color rgba="1 1 0 1"/>
      </material>
    </visual>
    <collision>
      <geometry>
        <box size="0.1 0.1 0.1"/>
      </geometry>
    </collision>
  </link>
  <link name="palm_R">
    <inertial>
      <mass value="0.5"/>
      <inertia ixx="0.01" iyy="0.01" izz="0.01"/>
    </inertial>
    <visual>
      <geometry>
        <box size="0.1 0.1 0.1"/>
      </geometry>
      <material name="palm_R_color">
        <color rgba="1 1 0 1"/>
      </material>
    </visual>
    <collision>
      <geometry>
        <box size="0.1 0.1 0.1"/>
      </geometry>
    </collision>
  </link>
  <link name="thigh_L">
    <inertial>
      <mass value="3"/>
      <inertia ixx="0.01" iyy="0.01" izz="0.01"/>
    </inertial>
    <visual>
      <geometry>
        <box size="0.15 0.15 0.4"/>
      </geometry>
      <material name="thigh_L_color">
        <color rgba="0 1 0 1"/>
      </material>
    </visual>
    <collision>
      <geometry>
        <box size="0.15 0.15 0.4"/>
      </geometry>
    </collision>
  </link>
  <link name="calf_L">
    <inertial>
      <mass value="2"/>
      <inertia ixx="0.01" iyy="0.01" izz="0.01"/>
    </inertial>
    <visual>
      <geometry>
        <box size="0.15 0.15 0.4"/>
      </geometry>
      <material name="calf_L_color">
        <color rgba="0 0.8 0 1"/>
      </material>
    </visual>
    <collision>
      <geometry>
        <box size="0.15 0.15 0.4"/>
      </geometry>
    </collision>
  </link>
  <link name="foot_L">
    <inertial>
      <mass value="1"/>
      <inertia ixx="0.01" iyy="0.01" izz="0.01"/>
    </inertial>
    <visual>
      <geometry>
        <box size="0.2 0.1 0.1"/>
      </geometry>
      <material name="foot_L_color">
        <color rgba="0.5 0.3 0 1"/>
      </material>
    </visual>
    <collision>
      <geometry>
        <box size="0.2 0.1 0.1"/>
      </geometry>
    </collision>
  </link>
  <link name="thigh_R">
    <inertial>
      <mass value="3"/>
      <inertia ixx="0.01" iyy="0.01" izz="0.01"/>
    </inertial>
    <visual>
      <geometry>
        <box size="0.15 0.15 0.4"/>
      </geometry>
      <material name="thigh_R_color">
        <color rgba="0 1 0 1"/>
      </material>
    </visual>
    <collision>
      <geometry>
        <box size="0.15 0.15 0.4"/>
      </geometry>
    </collision>
  </link>
  <link name="calf_R">
    <inertial>
      <mass value="2"/>
      <inertia ixx="0.01" iyy="0.01" izz="0.01"/>
    </inertial>
    <visual>
      <geometry>
        <box size="0.15 0.15 0.4"/>
      </geometry>
      <material name="calf_R_color">
        <color rgba="0 0.8 0 1"/>
      </material>
    </visual>
    <collision>
      <geometry>
        <box size="0.15 0.15 0.4"/>
      </geometry>
    </collision>
  </link>
  <link name="foot_R">
    <inertial>
      <mass value="1"/>
      <inertia ixx="0.01" iyy="0.01" izz="0.01"/>
    </inertial>
    <visual>
      <geometry>
        <box size="0.2 0.1 0.1"/>
      </geometry>
      <material name="foot_R_color">
        <color rgba="0.5 0.3 0 1"/>
      </material>
    </visual>
    <collision>
      <geometry>
        <box size="0.2 0.1 0.1"/>
      </geometry>
    </collision>
  </link>
  <joint name="neck" type="revolute">
    <parent link="torso"/>
    <child link="head"/>
    <origin xyz="0 0 0.35" rpy="0 0 0"/>
    <axis xyz="0 1 0"/>
  </joint>
  <joint name="shoulder_L" type="revolute">
    <parent link="torso"/>
    <child link="upper_arm_L"/>
    <origin xyz="0.2 0 0.25" rpy="0 0 0"/>
    <axis xyz="0 0 1"/>
  </joint>
  <joint name="elbow_L" type="revolute">
    <parent link="upper_arm_L"/>
    <child link="lower_arm_L"/>
    <origin xyz="0 0 -0.3" rpy="0 0 0"/>
    <axis xyz="0 0 1"/>
  </joint>
  <joint name="wrist_L" type="revolute">
    <parent link="lower_arm_L"/>
    <child link="palm_L"/>
    <origin xyz="0 0 -0.3" rpy="0 0 0"/>
    <axis xyz="0 0 1"/>
  </joint>
  <joint name="shoulder_R" type="revolute">
    <parent link="torso"/>
    <child link="upper_arm_R"/>
    <origin xyz="-0.2 0 0.25" rpy="0 0 0"/>
    <axis xyz="0 0 1"/>
  </joint>
  <joint name="elbow_R" type="revolute">
    <parent link="upper_arm_R"/>
    <child link="lower_arm_R"/>
    <origin xyz="0 0 -0.3" rpy="0 0 0"/>
    <axis xyz="0 0 1"/>
  </joint>
  <joint name="wrist_R" type="revolute">
    <parent link="lower_arm_R"/>
    <child link="palm_R"/>
    <origin xyz="0 0 -0.3" rpy="0 0 0"/>
    <axis xyz="0 0 1"/>
  </joint>
  <joint name="hip_L" type="revolute">
    <parent link="torso"/>
    <child link="thigh_L"/>
    <origin xyz="0.1 0 -0.3" rpy="0 0 0"/>
    <axis xyz="1 0 0"/>
  </joint>
  <joint name="knee_L" type="revolute">
    <parent link="thigh_L"/>
    <child link="calf_L"/>
    <origin xyz="0 0 -0.4" rpy="0 0 0"/>
    <axis xyz="1 0 0"/>
  </joint>
  <joint name="ankle_L" type="revolute">
    <parent link="calf_L"/>
    <child link="foot_L"/>
    <origin xyz="0 0 -0.4" rpy="0 0 0"/>
    <axis xyz="1 0 0"/>
  </joint>
  <joint name="hip_R" type="revolute">
    <parent link="torso"/>
    <child link="thigh_R"/>
    <origin xyz="-0.1 0 -0.3" rpy="0 0 0"/>
    <axis xyz="1 0 0"/>
  </joint>
  <joint name="knee_R" type="revolute">
    <parent link="thigh_R"/>
    <child link="calf_R"/>
    <origin xyz="0 0 -0.4" rpy="0 0 0"/>
    <axis xyz="1 0 0"/>
  </joint>
  <joint name="ankle_R" type="revolute">
    <parent link="calf_R"/>
    <child link="foot_R"/>
    <origin xyz="0 0 -0.4" rpy="0 0 0"/>
    <axis xyz="1 0 0"/>
  </joint>
</robot>
